Workbook

Sheet Programs of HUD
A1: PDF Page | B1: Program Name | C1: Administering Office | D1: Program Summary | E1: Statutory Authority | F1: CFR Citation (Regulations) | G1: Program Website(s)
A2: 6 | B2: The Violence Against Women Act (VAWA) | C2: Offices of the Secretary & Deputy Secretary | D2: Provides housing protections for survivors of domestic violence, dating violence, sexual assault, and stalking in covered housing programs. | E2: Chapter 2 of Subtitle N of the Violence Against Women Act of 1994 (34 U.S.C. 12471, et seq.); (34 U.S.C. 12491-12496). | F2: Regulations are found at 24 CFR part 5, subpart L and in individual program regulations. The Violence Against Women Act Reauthorization Act of 2022 (Public Law 117-103, approved March 15, 2022). | G2: https://www.hud.gov/vawa
A3: 7 | B3: Self-Help Housing Property Disposition Program | C3: Offices of the Secretary & Deputy Secretary | D3: This program makes surplus Federal properties available through sale at less than fair market value to States, their subdivisions and instrumentalities, and nonprofit organizations. | E3: 40 U.S.C. 550(f)(3). | G3: https://disposal.gsa.gov/s/
A4: 8 | B4: Capacity Building for Community Development and Affordable Housing (Section 4) | C4: Community Planning and Development (CPD) | D4: Grants to national intermediaries to develop the capacity and ability of community development corporations (CDCs) and community housing development organizations (CHDOs) to carry out community development and affordable housing activities that benefit low- and moderateincome families and persons. | E4: Section 4 of the HUD Demonstration Act of 1993 (42 U.S.C. 9816 note). | G4: https://www.hud.gov/program_offices/comm_planning/section-4
A5: 9 | B5: Community Development Block Grant Disaster Recovery (CDBG-DR) Assistance | C5: Community Planning and Development (CPD) | D5: Flexible grants to help the most impacted and distressed areas recover long-term after Presidentially declared disasters. | E5: CDBG-DR assistance is largely governed by specific appropriations acts, most recently Public Law 117-328, and it is also subject to provisions of Title I of the Housing and Community Development Act of 1974 (42 U.S.C. 5301, et seq.) (made applicable by appropriations acts unless waived) and certain provisions of the Robert T. Stafford Disaster Relief and Emergency Assistance Act (42 U.S.C. 5121, et seq.). | G5: https://www.hud.gov/program_offices/comm_planning/cdbg-dr
A6: 11 | B6: Community Development Block Grants (CDBG) (Entitlement) | C6: Community Planning and Development (CPD) | D6: Funding to help metropolitan cities and urban counties meet their housing and community development needs. | E6: Title I, Housing and Community Development Act of 1974 (Public Law 93383, approved August 22, 1974) (42 U.S.C. 5301, et seq.). | F6: CDBG Program regulations are at 24 CFR part 570 and consolidated plan regulations are at 24 CFR part 91. | G6: https://www.hud.gov/program_offices/comm_planning/cdbg
A7: 13 | B7: Community Development Block Grants for Insular Areas | C7: Community Planning and Development (CPD) | D7: Funding to help certain U.S. territories meet their housing and community development needs. | E7: Title I, Housing and Community Development Act of 1974 (42 U.S.C. 5301, et seq.). | F7: CDBG Program regulations are at 24 CFR part 570 and consolidated plan regulations are at 24 CFR part 91. | G7: https://www.hud.gov/program_offices/comm_planning/cdbg
A8: 14 | B8: Community Development Block Grants (Non-Entitlement) for States and Small Cities | C8: Community Planning and Development (CPD) | D8: Funding to help States and units of local government in non-entitlement areas meet their housing and community development needs. | E8: Title I, Housing and Community Development Act of 1974 (42 U.S.C. 5301, et seq.). | F8: CDBG program regulations are at 24 CFR part 570 and consolidated plan regulations are at 24 CFR part 91. | G8: https://www.hud.gov/program_offices/comm_planning/cdbg
A9: 15 | B9: Community Development Block Grants (Section 108 Loan Guarantee) | C9: Community Planning and Development (CPD) | D9: Loan guarantee assistance for community and economic development. | E9: Section 108 of the Housing and Community Development Act of 1974 (42 U.S.C. 5308). | F9: Regulations are at 24 CFR part 570. | G9: https://www.hud.gov/program_offices/comm_planning/section108
A10: 17 | B10: Continuum of Care Program | C10: Community Planning and Development (CPD) | D10: Promotes community-wide commitment to the goal of ending homelessness; provides funding for efforts to quickly re-house homeless individuals and families while minimizing trauma and dislocation; promotes access to and effective utilization of mainstream programs; and optimizes self-sufficiency among individuals and families experiencing homelessness. | E10: Subtitle C of Title IV of the McKinney-Vento Homeless Assistance Act (42 U.S.C. 11381-11389). | F10: Regulations are at 24 CFR part 578. | G10: https://www.hud.gov/program_offices/comm_planning/coc
A11: 18 | B11: Emergency Solutions Grants (ESG) Program | C11: Community Planning and Development (CPD) | D11: Formula grants to provide emergency assistance to people who are homeless or at risk of homelessness and help them quickly regain stability in permanent housing. | E11: Subtitle B of Title IV of the McKinney-Vento Homeless Assistance Act (42 U.S.C. 11371-11378). | F11: Regulations are at 24 CFR part 576. | G11: https://www.hud.gov/program_offices/comm_planning/esg
A12: 19 | B12: Federal Surplus Property for Use to Assist Persons Experiencing Homelessness (Title V) | C12: Community Planning and Development (CPD) | D12: Enables States, local governments, and qualified nonprofit organizations to use suitable and available Federal properties which are categorized as unutilized, underutilized, excess, or surplus, to assist persons experiencing homelessness. | E12: Title V of the McKinney-Vento Homeless Assistance Act of 1987 (42 U.S.C. 11411). | F12: Regulations are at 24 CFR part 581. | G12: https://www.hud.gov/program_offices/comm_planning/titlev
A13: 20 | B13: HOME Investment Partnerships | C13: Community Planning and Development (CPD) | D13: Grants to States, units of general local government, consortia, and insular areas (“participating jurisdictions”) to implement local housing strategies to increase affordable housing opportunities for low- and very low-income families. | E13: Title II of the Cranston-Gonzalez National Affordable Housing Act (42 U.S.C. 12721, et seq.). | F13: Regulations are at 24 CFR part 92 and consolidated plan regulations are at 24 CFR part 91. | G13: https://www.hud.gov/program_offices/comm_planning/home
A14: 22 | B14: Housing Opportunities for Persons with AIDS (HOPWA) | C14: Community Planning and Development (CPD) | D14: Formula grants and competitively awarded grants to provide housing assistance and related supportive services to meet the housing needs of low-income persons living with HIV/AIDS and their families. | E14: The AIDS Housing Opportunity Act, Subtitle D of Title VIII of the CranstonGonzalez National Affordable Housing Act (42 U.S.C. 12901, et seq.). | F14: Regulations are at 24 CFR part 574. | G14: https://www.hud.gov/program_offices/comm_planning/hopwa
A15: 23 | B15: Housing Trust Fund | C15: Community Planning and Development (CPD) | D15: Provides funds to States, State-designated entities, and insular areas for the construction, rehabilitation, and preservation of rental homes and for homeownership for extremely low- and very low-income families, including homeless families. Nature of the Program: The Housing Trust Fund (HTF) provides funding to construct, rehabilitate, and preserve permanent rental and homeownership housing, primarily for extremely low-income families. At least 80 percent of the funds must be used for the production, preservation, rehabilitation, or operation of rental housing. Up to 10 percent can be used for the following homeownership activities for first-time homebuyers: production, preservation, and rehabilitation; down payment assistance, closing cost assistance, and assistance for interest rate buy-downs. Up to 10 percent may be used for reasonable administrative and planning costs. In any fiscal year with an aggregate formula allocation under $1 billion, 100 percent of the grant funds must benefit extremely low-income families or families with incomes at or below the poverty line, whichever is greater. In any fiscal year with an aggregate formula allocation over $1 billion, at least 75 percent of grant funds must benefit extremely low-income families, and the remainder must benefit very low-income families. Eligible activities and expenses include real property acquisition, site improvements and development hard costs, related soft costs, demolition, financing costs, and relocation costs. HTF-assisted rental housing units must have a minimum affordability period of 30 years. The affordability period for homeownership housing ranges from 10 to 30 years, depending on the amount of per-unit homeownership assistance. | E15: Section 1338 of the Federal Housing Enterprises Financial Safety and Soundness Act of 1992 as amended (12 U.S.C. 4568). | F15: Regulations are at 24 CFR part 93 and consolidated plan regulations are at 24 CFR part 91. | G15: https://www.hud.gov/program_offices/comm_planning/htf
A16: 24 | B16: Rural Capacity Building for Community Development and Affordable Housing Grants Program | C16: Community Planning and Development (CPD) | D16: Program Grants to national organization intermediaries for rural housing development organizations, community development corporations (CDCs), community housing development organizations (CHDOs), local governments, and Indian tribes to carry out community development and affordable housing activities that benefit low- and moderate-income families and persons in rural areas. | E16: Consolidated Appropriations Act, 2023 (Public Law 117-328, approved December 29, 2022). | G16: https://www.hudexchange.info/programs/rural-capacity-building/
A17: 25 | B17: Self-Help Homeownership Opportunity Program (SHOP) | C17: Community Planning and Development (CPD) | D17: Grants to national and regional nonprofits to fund opportunities for self-help homeownership housing. | E17: Section 11 of the Housing Opportunity Program Extension Act of 1996 (42 U.S.C. 12805 note). | G17: https://www.hud.gov/program_offices/comm_planning/shop
A18: 26 | B18: Energy Efficient Mortgage Program | C18: Office of Housing — Single Family Housing Programs | D18: Mortgage insurance to finance cost effective energy efficiency improvements. | E18: Section 513 of the Housing and Community Development Act of 1992 (Public Law 102-550, approved October 28, 1992) (12 U.S.C. 1701z-16). | F18: Regulations are at 24 CFR 203.18(i). | G18: https://www.hud.gov/program_offices/housing/sfh/eem/energy-r
A19: 27 | B19: Good Neighbor Next Door Sales Program (GNND) | C19: Office of Housing — Single Family Housing Programs | D19: Provides eligible law enforcement officers, teachers (pre-Kindergarten through 12th grade), firefighters, and emergency medical technicians with the opportunity to purchase and live in homes located in revitalization areas at a fifty percent discount off the list price of eligible properties. | E19: Section 204 of the National Housing Act (12 U.S.C. 1710). | F19: Regulations are at 24 CFR part 291, subpart F. | G19: https://www.hud.gov/program_offices/housing/sfh/reo/goodn/gnndabot
A20: 28 | B20: Home Equity Conversion Mortgage (HECM) (Section 255) | C20: Office of Housing — Single Family Housing Programs | D20: Mortgage insurance for reverse mortgages that provide borrowers who are at least 62 years old the ability to convert some of the equity in their primary residences into fixed interest rate mortgages with a single disbursement lump sum payment or adjustable interest rate mortgages with monthly streams of income or lines of credit, or a combination of both. | E20: Section 255 of the National Housing Act (12 U.S.C. 1715z-20). | F20: Regulations are at 24 CFR part 206. | G20: https://www.hud.gov/program_offices/housing/sfh/hecm/hecmabou
A21: 29 | B21: Insurance for Adjustable Rate Mortgages (ARMs) (Section 251) | C21: Office of Housing — Single Family Housing Programs | D21: Mortgage insurance for adjustable rate forward mortgages (ARMs). | E21: Section 251 of the National Housing Act (12 U.S.C. 1715z-16). | F21: Regulations are at 24 CFR 203.49. | G21: https://www.hud.gov/program_offices/housing/sfh/ins/251--df
A22: 30 | B22: Insured Mortgages on Hawaiian Home Lands (Section 247) | C22: Office of Housing — Single Family Housing Programs | D22: Insures loans to Native Hawaiians to purchase one- to four-family dwellings located on Hawaiian Home Lands, similar to Section 203(b) loans with certain exceptions. | E22: Section 247 of the National Housing Act (12 U.S.C. 1715z-12). | F22: Regulations are at 24 CFR 203.43i. | G22: https://www.hud.gov/program_offices/housing/sfh/ins/sfh_hawaiian_home_lands
A23: 31 | B23: Loss Mitigation | C23: Office of Housing — Single Family Housing Programs | D23: Measures that allow lenders to effectively work with delinquent borrowers of FHA-insured single family loans to find solutions to avoid foreclosure. | E23: Sections 204(a) and 230 of the National Housing Act (12 U.S.C. 1710(a) and 12 U.S.C. 1715u). | F23: Regulations are at 24 CFR part 203. | G23: https://www.hud.gov/program_offices/housing/sfh/nsc/lossmit
A24: 32 | B24: Manufactured Homes Loan Insurance (Title I) | C24: Office of Housing — Single Family Housing Programs | D24: Mortgage insurance for private lending institutions to finance the purchase or refinance of a new or existing manufactured home, a manufactured home lot, or a lot plus manufactured home. | E24: Section 2 of Title I of the National Housing Act (12 U.S.C. 1703). | F24: Regulations are at 24 CFR part 201. | G24: https://www.hud.gov/program_offices/housing/sfh/title/manuf14
A25: 33 | B25: Mortgage Insurance for Disaster Victims (Section 203) | C25: Office of Housing — Single Family Housing Programs | D25: Mortgage insurance for victims of a Presidentially declared major disaster who have lost their homes and are in the process of rebuilding or buying another single family home. | E25: Section 203(h) of the National Housing Act (12 U.S.C. 1709(h)). | F25: Regulations are at 24 CFR 203.18. | G25: https://www.hud.gov/program_offices/housing/sfh/ins/203h-dft
A26: 34 | B26: Mortgage Insurance for One- to Four-Family Homes (Section 203) | C26: Office of Housing — Single Family Housing Programs | D26: Mortgage insurance for purchasing or refinancing a primary residence. | E26: Sections 203(b) and 214 of the National Housing Act (12 U.S.C. 1709(b) and 12 U.S.C. 1715d). | F26: Regulations are at 24 CFR part 203. | G26: https://www.hud.gov/program_offices/housing/sfh/ins/203b--df
A27: 35 | B27: Mortgage Insurance Programs on Indian Reservations and Other Restricted Lands (Section 248) | C27: Office of Housing — Single Family Housing Programs | D27: Mortgage insurance for loans made to Native Americans to buy, build, or rehabilitate houses on Indian trust or otherwise restricted land; fundamentally the same as Section 203(b) loans. | E27: Section 248 of the National Housing Act (12 U.S.C. 1715z-13). | F27: Regulations are at 24 CFR 203.43h. | G27: https://www.hud.gov/program_offices/housing/sfh/ins/sfh248
A28: 36 | B28: Property Improvement Loan Insurance (Title I) | C28: Office of Housing — Single Family Housing Programs | D28: Mortgage insurance for loans to finance or refinance the alteration, repair or improvement of property, for the purchase and installation of fire safety equipment in existing health care facilities, and for the preservation of historic structures. | E28: Section 2 of Title I of the National Housing Act (12 U.S.C. 1703). | F28: Regulations are at 24 CFR part 201. | G28: https://www.hud.gov/program_offices/housing/sfh/title
A29: 37 | B29: Rehabilitation Loan Mortgage Insurance (Section 203(k)) | C29: Office of Housing — Single Family Housing Programs | D29: Mortgage insurance to finance the rehabilitation or purchase and rehabilitation of one- to fourunit structures. | E29: Section 203(k) of the National Housing Act (12 U.S.C. 1709(k)). | F29: Regulations are in 24 CFR 203.50. | G29: https://www.hud.gov/program_offices/housing/sfh/203k/203k--df
... A47: 56 | B47: Housing Counseling Program | C47: Office of Housing — Office of Housing Counseling | D47: Provides regulatory oversight and capacity building to HUD-approved Housing Counseling Agencies and HUD-certified counselors and awards grants to facilitate housing counseling services, addressing such needs as purchasing or renting a home, preventing foreclosure and eviction, and diminishing homelessness. | E47: Section 4(g)(3) of the Department of Housing and Urban Development Act of 1965 (42 U.S.C. 3533(g)(3)) and section 106 of the Housing and Urban Development Act of 1968 (12 U.S.C. 1701x). | F47: Regulations are at 24 CFR part 206, subpart E and part 214. | G47: https://www.hudexchange.info/programs/housingcounseling/program-description/
A48: 57 | B48: Book-Rich Environments Initiative | C48: Public and Indian Housing (PIH) — Public Housing Programs | D48: Collaboration aimed to transform public housing agencies (PHAs) into book-rich environments by providing diverse, high-quality books and other literacy tools to children and families living in HUD-assisted housing. | E48: Section 501 of the Housing and Urban Development Act of 1970 (12 U.S.C. 1701z-1). | G48: https://www.hud.gov/program_offices/public_indian_housing/bre
A49: 58 | B49: Choice Neighborhoods | C49: Public and Indian Housing (PIH) — Public Housing Programs | D49: Competitive grant program to develop severely distressed HUD housing through a comprehensive approach which transforms neighborhoods of poverty into vibrant, mixed-income neighborhoods. | E49: Choice Neighborhoods is authorized through annual appropriations acts, most recently the Consolidated Appropriations Act, 2024 (Public Law 118-42, approved March 9, 2024); section 24 of the United States Housing Act of 1937 (42 U.S.C. 1437v) . | G49: https://www.hud.gov/cn
A50: 59 | B50: ConnectHomeUSA | C50: Public and Indian Housing (PIH) — Public Housing Programs | D50: Platform for public-private collaboration to improve educational, employment, and health outcomes of HUD-assisted households by narrowing the digital divide. | E50: Section 501 of the Housing and Urban Development Act of 1970 (12 U.S.C. 1701z-1); notice published in the Federal Register on April 3, 2015, at 80 FR 18248.
A51: 60 | B51: Family Self-Sufficiency (FSS) Program | C51: Public and Indian Housing (PIH) — Public Housing Programs | D51: Promotes the development of local strategies to coordinate public and private resources that help housing choice voucher program participants, public housing tenants, and tenants in the Section 8 Project-Based Rental Assistance (PBRA) program to obtain employment that aims to enable participating families to achieve economic independence and reduce dependence on welfare assistance and rental subsidies. | E51: Section 23 of the United States Housing Act of 1937 (42 U.S.C. 1437u). | F51: Regulations are at 24 CFR part 984. | G51: https://www.hud.gov/program_offices/public_indian_housing/programs/hcv/fss
A52: 61 | B52: Housing Choice Voucher Program | C52: Public and Indian Housing (PIH) — Public Housing Programs | D52: Rental subsidies for tenants to rent units in the private market. | E52: Section 8 of the United States Housing Act of 1937 (42 U.S.C. 1437f). | F52: Regulations are at 24 CFR part 5 (certain cross-cutting requirements); 24 CFR part 982 (Section 8 Tenant-Based Housing Choice Voucher Program); 24 CFR part 984 (Section 8 and Public Housing Family Self-Sufficiency Program); and 24 CFR part 985 (Section 8 Management Assessment Program (SEMAP)). | G52: https://www.hud.gov/program_offices/public_indian_housing/programs/hcv/about/
A53: 64 | B53: Jobs Plus Initiative | C53: Public and Indian Housing (PIH) — Public Housing Programs | D53: Competitive grant program to increase earnings and advance employment outcomes for public housing residents. | E53: The Jobs Plus Initiative is authorized through annual appropriations acts, most recently the Consolidated Appropriations Act, 2024 (Public Law 118-42, approved March 9, 2024). | G53: https://www.hud.gov/program_offices/public_indian_housing/jpi
A54: 65 | B54: Moving to Work (MTW) Demonstration | C54: Public and Indian Housing (PIH) — Public Housing Programs | D54: Allows selected PHAs to test new ways of providing housing assistance intended to improve cost-effectiveness, promote self-sufficiency of assisted households, or increase housing choices for low-income families. | E54: Section 204 of the Omnibus Consolidated Rescissions and Appropriations Act of 1996 (Public Law 104-134, approved April 26, 1996). Additional MTW agencies authorized by section 599H of the Departments of Veterans Affairs and Housing and Urban Development, and Independent Agencies Appropriation Act, 1999 (Public Law 105-276, approved October 21, 1998); section 230 of the Consolidated Appropriations Act, 2008 (Public Law 110-161, approved December 26, 2007); section 232 of the Consolidated Appropriations Act, 2010 (Public Law 111-117, approved December 16, 2009); section 1101 of the Department of Defense and FullYear Continuing Appropriations Act, 2011 (Public Law 112-10, approved April 15, 2011); and section 239 of the Consolidated Appropriations Act, 2016 (Public Law 114-113, approved December 18, 2015). | G54: https://www.hud.gov/program_offices/public_indian_housing/programs/ph/mtw
A55: 66 | B55: Project-Based Voucher Program | C55: Public and Indian Housing (PIH) — Public Housing Programs | D55: Rental assistance for eligible families who live in specific housing developments or units. | E55: Section 8(o)(13) of the United States Housing Act of 1937 (42 U.S.C. 1437f(o)(13)). | F55: Regulations are at 24 CFR part 983. | G55: https://www.hud.gov/program_offices/public_indian_housing/programs/hcv/project
A56: 67 | B56: Public Housing Capital Fund | C56: Public and Indian Housing (PIH) — Public Housing Programs | D56: Funding for capital improvements to public housing units. | E56: Section 9(d) and section 30 of the United States Housing Act of 1937 (42 U.S.C. 1437g(d) and 1437z-2). | F56: Regulations are at 24 CFR part 905. | G56: https://www.hud.gov/program_offices/public_indian_housing/programs/ph/capfund
A57: 68 | B57: Public Housing Homeownership (Section 32) | C57: Public and Indian Housing (PIH) — Public Housing Programs | D57: Sale of public housing units to low-income families. | E57: Section 32 of the United States Housing Act of 1937 (42 U.S.C. 1437z-4). | F57: Regulations are at 24 CFR part 906. | G57: https://www.hud.gov/program_offices/public_indian_housing/centers/sac/homeownership/
...

Sheet About
A1: Programs of HUD — 2025 Reference Spreadsheet
A3: Source: U.S. Department of Housing and Urban Development, "Programs of HUD 2025" (Major Mortgage, Grant, Assistance, and Regulatory Programs, 2025).
A4: Original PDF filename: HUDPrograms2025.pdf (109 pages, dated December 17, 2024).
A6: Coverage: All programs listed in the HUD 2025 reference document, including:
A7: • Active programs in each program office (rows grouped by Administering Office)
A8: • Temporary programs authorized through specific appropriations acts
A9: • Related agencies (NeighborWorks America, U.S. Interagency Council on Homelessness)
A10: • Inactive programs (programs receiving no new funds or only renewal funding)
A12: Total programs: 102
A14: Column notes:
A15: • Program Summary: drawn from the brief introductory description in each program's PDF entry (the italicized teaser sentence(s) appearing immediately under the program title in the source document). Trimmed to two sentences where the original was longer.
A16: • Statutory Authority: extracted from each program's "Legal Authority" section. For Temporary Programs, the authorizing appropriations act (with Public Law number) is used.
... A98: Columns G–H (added Oct. 2, 2026): 'Why it's in this group' explains the placement (usually the authorizing law; sometimes that law routes the money through another program's statute, e.g., EHV and RAD to Section 8 or CDBG-DR and RHP to HCDA Title I, or leaves the definition to HUD), and 'Authorizing law' cites the statute or appropriations act.

Sheet FPI (HUD)
A1: AL Number | B1: Program Title | C1: Popular Name | D1: Agency | E1: Sub-Agency | F1: Objective | G1: Assistance Types | H1: Beneficiary Types | I1: Applicant Types | J1: FY2025 Obligation — FPI Headline ($, SAM estimate) | K1: FY2024 Obligation ($, USAspending actual) | L1: FY2023 Obligation ($, USAspending actual) | M1: Obligations (raw JSON, all years)
A2: 14.021 | B2: Green and Resilient Retrofit Program | C2: GRRP | D2: Department of Housing and Urban Development | E2: Assistant Secretary for Housing -- Federal Housing Commissioner | F2: The Green and Resilient Retrofit Program offers loans and grants for HUD-assisted multifamily properties to improve energy or water efficiency, enhance indoor air quality or sustainability, implement the use of zero-emission electricity generation, low-emission building materials or processes, energy storage, or building electrification strategies, or address climate resilience. | G2: Direct Loans | H2: Private nonprofit institution/organization,Profit organization,Public nonprofit institution/organization | I2: Private nonprofit institution/organization (includes institutions of higher education and hospitals),Profit organization,Public nonprofit institution/organization (includes institutions of higher education and hospitals) | J2: 0 | K2: 590926365 | L2: 9025948 | M2: [{"x":"2023","sam_estimate":0.0,"sam_actual":75000000.0,"usa_spending_actual":9025948.0},{"x":"2024","sam_estimate":0.0,"sam_actual":87000000.0,"usa_spending_actual":590926365.0},{"x":"2025","sam_estimate":0.0,"sam_actual":0.0,"usa_spending_actual":19471823.2}]
A3: 14.022 | B3: Housing Counseling Program Homeownership Initiative | D3: Department of Housing and Urban Development | E3: Assistant Secretary for Housing -- Federal Housing Commissioner | F3: The Homeownership Initiative (HI) helps to bridge the homeownership gap by increasing homeownership rates among historically underserved borrowers. HUD-approved Intermediaries, Multi-State Organizations, and State Housing Finance Agencies will receive fixed amount awards to provide culturally sensitive linguistically appropriate pre-purchase and post-purchase counseling that results in home purchase. | G3: Project Grants | I3: Local (includes State-designated lndian Tribes, excludes institutions of higher education and hospitals,Other private institutions/organizations,Other public institution/organization,Private nonprofit institution/organization (includes institutions of higher education and hospitals),Public nonprofit institution/organization (includes institutions of higher education and hospitals),State,State (includes District of Columbia, public institutions of higher education and hospitals) | J3: 0 | K3: 10000000 | L3: 0 | M3: [{"x":"2023","sam_estimate":0.0,"sam_actual":67000000.0,"usa_spending_actual":0.0},{"x":"2024","sam_estimate":0.0,"sam_actual":61000000.0,"usa_spending_actual":10000000.0},{"x":"2025","sam_estimate":0.0,"sam_actual":0.0,"usa_spending_actual":-66186.5}]
A4: 14.023 | B4: Community Development Block Grant- PRO Housing Competition | C4: PRO Housing | D4: Department of Housing and Urban Development | E4: Assistant Secretary for Community Planning and Development | F4: PRO (Pathways to Removing Obstacles) to Housing provides competitive grant funds for the identification and removal of barriers to affordable housing production and preservation. | G4: Project Grants | I4: Government - General,Local (includes State-designated lndian Tribes, excludes institutions of higher education and hospitals,Native American Organizations (includes lndian groups, cooperatives, corporations, partnerships, associations),Non-Government - General,Other private institutions/organizations,Other public institution/organization,State | J4: 0 | K4: 84935900 | L4: 0 | M4: [{"x":"2023","sam_estimate":0.0,"sam_actual":10000000.0,"usa_spending_actual":0.0},{"x":"2024","sam_estimate":0.0,"sam_actual":84935898.0,"usa_spending_actual":84935899.92},{"x":"2025","sam_estimate":0.0,"sam_actual":100064101.0,"usa_spending_actual":0.0}]
A5: 14.024 | B5: Community Development Block Grant- PRICE Competition | C5: CDBG-PRICE | D5: Department of Housing and Urban Development | E5: Assistant Secretary for Community Planning and Development | F5: The Community Development Block Grant - Preservation and Reinvestment Initiative for Community Enhancement (CDBG-PRICE) competition provides competitive grant funds to help preserve and revitalize manufactured housing and eligible manufactured housing communities and assist in the redevelopment of manufactured housing communities as replacement housing that is affordable. | G5: Project Grants | I5: Federally Recognized lndian Tribal Governments,Government - General,Local (includes State-designated lndian Tribes, excludes institutions of higher education and hospitals,Minority group,Native American Organizations (includes lndian groups, cooperatives, corporations, partnerships, associations),Non-Government - General,Profit organization,Quasi-public nonprofit institution/organization,State | J5: 0 | K5: 0 | L5: 0 | M5: [{"x":"2023","sam_estimate":0.0,"sam_actual":225000000.0,"usa_spending_actual":0.0},{"x":"2024","sam_estimate":0.0,"sam_actual":0.0,"usa_spending_actual":0.0},{"x":"2025","sam_estimate":0.0,"sam_actual":0.0,"usa_spending_actual":0.0}]
A6: 14.108 | B6: Rehabilitation Mortgage Insurance | C6: FHA Rehabilitation Mortgage- 203(k) | D6: Department of Housing and Urban Development | E6: Assistant Secretary for Housing -- Federal Housing Commissioner | F6: FHA's 203(k) Rehabilitation Mortgage program is HUD's primary program for the rehabilitation and repair of one to four family properties. It is an important tool for community and neighborhood revitalization and for expanding homeownership opportunities. The 203(k) program works with either a purchase or refinance transaction and allows the cost of making repairs and/or improvement to be included in the loan amount. | G6: Guaranteed / Insured Loans | H6: Anyone/general public,Individual/Family | I6: Individual/Family | J6: 0 | K6: 0 | L6: 0 | M6: [{"x":"2023","sam_estimate":0.0,"sam_actual":0.0,"usa_spending_actual":0.0},{"x":"2024","sam_estimate":0.0,"sam_actual":0.0,"usa_spending_actual":0.0},{"x":"2025","sam_estimate":0.0,"sam_actual":0.0,"usa_spending_actual":0.0}]
A7: 14.110 | B7: Manufactured Home Loan Insurance (Title I) | C7: Manufactured Home Loan Insurance (Title I) | D7: Department of Housing and Urban Development | E7: Assistant Secretary for Housing -- Federal Housing Commissioner | F7: To help people purchase a manufactured home or refinance an existing manufactured home loan. mortgage. | G7: Sale, Exchange, or Donation of Property or Goods | H7: Anyone/general public,Individual/Family | I7: Individual/Family | J7: 0 | K7: 0 | L7: 0 | M7: [{"x":"2023","sam_estimate":0.0,"sam_actual":0.0,"usa_spending_actual":0.0},{"x":"2024","sam_estimate":0.0,"sam_actual":4000000.0,"usa_spending_actual":0.0},{"x":"2025","sam_estimate":0.0,"sam_actual":0.0,"usa_spending_actual":0.0}]
A8: 14.117 | B8: Mortgage Insurance Homes | C8: FHA Home Mortgage Insurance- 203(b) | D8: Department of Housing and Urban Development | E8: Assistant Secretary for Housing -- Federal Housing Commissioner | F8: Helps enable people to purchase a home or refinance an existing mortgage. | G8: Guaranteed / Insured Loans | H8: Anyone/general public,Individual/Family | I8: Individual/Family | J8: 0 | K8: 0 | L8: 0 | M8: [{"x":"2023","sam_estimate":0.0,"sam_actual":195799000.0,"usa_spending_actual":0.0},{"x":"2024","sam_estimate":0.0,"sam_actual":225000000.0,"usa_spending_actual":0.0},{"x":"2025","sam_estimate":0.0,"sam_actual":0.0,"usa_spending_actual":0.0}]
A9: 14.119 | B9: Mortgage Insurance Homes for Disaster Victims | C9: Mortgage Insurance for DIsaster Victims- 203(h) | D9: Department of Housing and Urban Development | E9: Assistant Secretary for Housing -- Federal Housing Commissioner | F9: To help victims of a Presidentially-declared disaster whose home was destroyed undertake homeownership on a sound basis. | G9: Sale, Exchange, or Donation of Property or Goods | H9: Anyone/general public,Individual/Family | I9: Individual/Family | J9: 0 | K9: 0 | L9: 0 | M9: [{"x":"2023","sam_estimate":0.0,"sam_actual":0.0,"usa_spending_actual":0.0},{"x":"2024","sam_estimate":0.0,"sam_actual":0.0,"usa_spending_actual":0.0},{"x":"2025","sam_estimate":0.0,"sam_actual":0.0,"usa_spending_actual":0.0}]
A10: 14.122 | B10: Mortgage Insurance Homes in Urban Renewal Areas | C10: (220 Homes) | D10: Department of Housing and Urban Development | E10: Assistant Secretary for Housing -- Federal Housing Commissioner | F10: To help eligible entities to purchase and/or rehabilitate homes in urban renewal areas. | G10: Guaranteed / Insured Loans | H10: Anyone/general public,Individual/Family | I10: Anyone/general public,Individual/Family,Local (includes State-designated lndian Tribes, excludes institutions of higher education and hospitals,Non-Government - General,Other private institutions/organizations,Other public institution/organization,Private nonprofit institution/organization (includes institutions of higher education and hospitals),Profit organization,Public nonprofit institution/organization (includes institutions of higher education and hospitals),Sponsored organization,State | J10: 0 | K10: 0 | L10: 0 | M10: [{"x":"2023","sam_estimate":0.0,"sam_actual":0.0,"usa_spending_actual":0.0},{"x":"2024","sam_estimate":0.0,"sam_actual":0.0,"usa_spending_actual":0.0},{"x":"2025","sam_estimate":0.0,"sam_actual":0.0,"usa_spending_actual":0.0}]
A11: 14.126 | B11: Mortgage Insurance Cooperative Projects | C11: Cooperative Housing Mortgage Insurance - Section 213 | D11: Department of Housing and Urban Development | E11: Assistant Secretary for Housing -- Federal Housing Commissioner | F11: Enables nonprofit cooperative ownership housing corporations or trusts to develop or sponsor the development of housing projects to be operated as cooperatives. Section 213 allows investors to provide good quality multifamily housing to be sold to such nonprofit corporations or trusts upon completion of construction or rehabilitation. | G11: Guaranteed / Insured Loans | H11: Private nonprofit institution/organization,Profit organization,Public nonprofit institution/organization,Sponsored organization | I11: Private nonprofit institution/organization (includes institutions of higher education and hospitals),Public nonprofit institution/organization (includes institutions of higher education and hospitals),Quasi-public nonprofit institution/organization | J11: 0 | K11: 0 | L11: 0 | M11: [{"x":"2023","sam_estimate":0.0,"sam_actual":0.0,"usa_spending_actual":0.0},{"x":"2024","sam_estimate":0.0,"sam_actual":0.0,"usa_spending_actual":0.0},{"x":"2025","sam_estimate":0.0,"sam_actual":0.0,"usa_spending_actual":0.0}]
A12: 14.128 | B12: Mortgage Insurance Hospitals | C12: (Section 242 - Mortgage Insurance for Hospitals) | D12: Department of Housing and Urban Development | E12: Assistant Secretary for Housing -- Federal Housing Commissioner | F12: To facilitate the affordable financing of hospitals for the care and treatment of persons who are acutely ill or who otherwise require medical care and related services of the kind customarily furnished only or most effectively by hospitals. | G12: Guaranteed / Insured Loans | H12: Disabled (e.g. Deaf, Blind, Physically Disabled),Individual/Family,Physically Afflicted (e.g. TB, Arthritis, Heart Disease) | I12: Private nonprofit institution/organization (includes institutions of higher education and hospitals),Profit organization | J12: 0 | K12: 0 | L12: 0 | M12: [{"x":"2023","sam_estimate":0.0,"sam_actual":482000000.0,"usa_spending_actual":0.0},{"x":"2024","sam_estimate":0.0,"sam_actual":960000000.0,"usa_spending_actual":0.0},{"x":"2025","sam_estimate":0.0,"sam_actual":0.0,"usa_spending_actual":0.0}]
A13: 14.129 | B13: Mortgage Insurance Nursing Homes, Intermediate Care Facilities, Board and Care Homes and Assisted Living Facilities | C13: Section (232) | D13: Department of Housing and Urban Development | E13: Assistant Secretary for Housing -- Federal Housing Commissioner | F13: To provide mortgage insurance to HUD-approved lenders to facilitate the construction or rehabilitation of nursing homes, intermediate care facilities, board and care homes and assisted living facilities, to allow purchase or refinancing with or without repairs of projects not requiring substantial rehabilitation, and to provide loan insurance to install fire safety equipment. | G13: Guaranteed / Insured Loans | H13: Disabled (e.g. Deaf, Blind, Physically Disabled),Physically Afflicted (e.g. TB, Arthritis, Heart Disease) | I13: Other private institutions/organizations,Private nonprofit institution/organization (includes institutions of higher education and hospitals),Profit organization,Specialized group (e.g. health professionals, students, veterans) | J13: 0 | K13: 0 | L13: 0 | M13: [{"x":"2023","sam_estimate":0.0,"sam_actual":3142000000.0,"usa_spending_actual":0.0},{"x":"2024","sam_estimate":0.0,"sam_actual":3142000000.0,"usa_spending_actual":0.0},{"x":"2025","sam_estimate":0.0,"sam_actual":0.0,"usa_spending_actual":0.0}]
A14: 14.133 | B14: Mortgage Insurance Purchase of Units in Condominiums | C14: Mortgage Insurance- Condominium Units | D14: Department of Housing and Urban Development | E14: Assistant Secretary for Housing -- Federal Housing Commissioner | F14: To enable individuals and families to purchase or refinance eligible units in condominium projects. | G14: Guaranteed / Insured Loans | H14: Anyone/general public,Individual/Family | I14: Individual/Family | J14: 0 | K14: 0 | L14: 0 | M14: [{"x":"2023","sam_estimate":0.0,"sam_actual":0.0,"usa_spending_actual":0.0},{"x":"2024","sam_estimate":0.0,"sam_actual":0.0,"usa_spending_actual":0.0},{"x":"2025","sam_estimate":0.0,"sam_actual":0.0,"usa_spending_actual":0.0}]
A15: 14.134 | B15: Mortgage Insurance Rental Housing | C15: Mortgage Insurance for Rental Housing -Section 207 | D15: Department of Housing and Urban Development | E15: Assistant Secretary for Housing -- Federal Housing Commissioner | F15: HUD insures mortgage loans to finance the construction or rehabilitation of a broad range of multifamily rental housing through a variety of programs linked in the Related Federal Assistance section. Though Section 207 itself is no longer active, this assistance listing is used to provide total FHA multifamily mortgage commitments across those programs. Due to challenges in breaking out projected commitments by each listing, the activity is summed and reported here. | G15: Guaranteed / Insured Loans | H15: Anyone/general public,Individual/Family | I15: Other private institutions/organizations,Private nonprofit institution/organization (includes institutions of higher education and hospitals),Profit organization | J15: 0 | K15: 0 | L15: 0 | M15: [{"x":"2023","sam_estimate":0.0,"sam_actual":19214000000.0,"usa_spending_actual":0.0},{"x":"2024","sam_estimate":0.0,"sam_actual":17513000000.0,"usa_spending_actual":0.0},{"x":"2025","sam_estimate":0.0,"sam_actual":0.0,"usa_spending_actual":0.0}]
A16: 14.135 | B16: Mortgage Insurance Rental and Cooperative Housing for Moderate Income Families and Elderly, Market Interest Rate | C16: New Construction or Substantial Rehabilitation of Rental Housing -221(d)(4) | D16: Department of Housing and Urban Development | E16: Assistant Secretary for Housing -- Federal Housing Commissioner | F16: Section 221(d)(4) insures mortgage loans to facilitate the new construction or substantial rehabilitation of multifamily rental or cooperative housing for moderate-income families, elderly, and the handicapped. Single Room Occupancy (SRO) projects may also be insured under this section. (See program 14.184). | G16: Guaranteed / Insured Loans | H16: Anyone/general public,Individual/Family,Private nonprofit institution/organization,Profit organization,Public nonprofit institution/organization | I16: Individual/Family,Private nonprofit institution/organization (includes institutions of higher education and hospitals),Profit organization,Public nonprofit institution/organization (includes institutions of higher education and hospitals) | J16: 0 | K16: 0 | L16: 0 | M16: [{"x":"2023","sam_estimate":0.0,"sam_actual":0.0,"usa_spending_actual":0.0},{"x":"2024","sam_estimate":0.0,"sam_actual":0.0,"usa_spending_actual":0.0},{"x":"2025","sam_estimate":0.0,"sam_actual":0.0,"usa_spending_actual":0.0}]
A17: 14.138 | B17: Mortgage Insurance Rental Housing for the Elderly | C17: New Construction and Substantial Rehabilitation for Rental Housing for the Elderly - Section 231 | D17: Department of Housing and Urban Development | E17: Assistant Secretary for Housing -- Federal Housing Commissioner | F17: To provide quality rental housing for the elderly. | G17: Guaranteed / Insured Loans | H17: Anyone/general public,Disabled (e.g. Deaf, Blind, Physically Disabled),Physically Afflicted (e.g. TB, Arthritis, Heart Disease),Private nonprofit institution/organization,Profit organization,Public nonprofit institution/organization,Senior Citizen (60+) | I17: Private nonprofit institution/organization (includes institutions of higher education and hospitals),Profit organization,Public nonprofit institution/organization (includes institutions of higher education and hospitals),Specialized group (e.g. health professionals, students, veterans) | J17: 0 | K17: 0 | L17: 0 | M17: [{"x":"2023","sam_estimate":0.0,"sam_actual":0.0,"usa_spending_actual":0.0},{"x":"2024","sam_estimate":0.0,"sam_actual":0.0,"usa_spending_actual":0.0},{"x":"2025","sam_estimate":0.0,"sam_actual":0.0,"usa_spending_actual":0.0}]
... A40: 14.248 | B40: Community Development Block Grants Section 108 Loan Guarantees | C40: (Section 108) | D40: Department of Housing and Urban Development | E40: Assistant Secretary for Community Planning and Development | F40: To provide communities with a source of financing for economic development, housing rehabilitation, public facilities, and large scale physical development projects. | G40: Guaranteed / Insured Loans | H40: Individual/Family,Low Income,Moderate Income | I40: Government - General,Other public institution/organization,State,U.S. Territories and possessions | J40: 0 | K40: 0 | L40: 0 | M40: [{"x":"2023","sam_estimate":0.0,"sam_actual":300000000.0,"usa_spending_actual":0.0},{"x":"2024","sam_estimate":0.0,"sam_actual":400000000.0,"usa_spending_actual":0.0},{"x":"2025","sam_estimate":0.0,"sam_actual":0.0,"usa_spending_actual":0.0}]
A41: 14.249 | B41: Section 8 Moderate Rehabilitation Single Room Occupancy | D41: Department of Housing and Urban Development | E41: Assistant Secretary for Community Planning and Development | F41: The Section 8 Moderate Rehabilitation Single Room Occupancy Program provides rental assistance to homeless individuals. Under the program, HUD entered into Annual Contributions Contracts (ACCs) with public housing agencies (PHAs) in connection with the moderate rehabilitation of residential properties that, when rehabilitation is completed, will contain multiple single room dwelling units. Funding for new projects ceased after 2011. Expiring contracts are now renewed. | G41: Project Grants | H41: Individual/Family | I41: Private nonprofit institution/organization (includes institutions of higher education and hospitals) | J41: 0 | K41: 67118327 | L41: 64836067 | M41: [{"x":"2023","sam_estimate":0.0,"sam_actual":0.0,"usa_spending_actual":64836067.0},{"x":"2024","sam_estimate":0.0,"sam_actual":0.0,"usa_spending_actual":67118327.0},{"x":"2025","sam_estimate":0.0,"sam_actual":0.0,"usa_spending_actual":5885553.0}]
A42: 14.251 | B42: Economic Development Initiative, Community Project Funding, and Miscellaneous grants | C42: Congressional Grants | D42: Department of Housing and Urban Development | E42: Office of Community Planning and Development | F42: The annual appropriation of funds to the Department and the accompanying Conference Report or Congressional Record accompanying the appropriation set forth grants in a specified amount to designated organizations for the activities specified by Congress. | G42: Project Grants | H42: Federal,Federally Recognized Indian Tribal Governments,Local,Native American Organizations,Other private institution/organization,Other public institution/organization,Preschool,Private nonprofit institution/organization,Public nonprofit institution/organization,Quasi-public nonprofit organization,School,State,U.S. Territories | I42: Local (includes State-designated lndian Tribes, excludes institutions of higher education and hospitals,Native American Organizations (includes lndian groups, cooperatives, corporations, partnerships, associations),Public nonprofit institution/organization (includes institutions of higher education and hospitals),State (includes District of Columbia, public institutions of higher education and hospitals) | J42: 0 | K42: 11423477 | L42: 2815228723 | M42: [{"x":"2023","sam_estimate":0.0,"sam_actual":4498694848.0,"usa_spending_actual":2815228723.0},{"x":"2024","sam_estimate":0.0,"sam_actual":0.0,"usa_spending_actual":11423477.0},{"x":"2025","sam_estimate":0.0,"sam_actual":0.0,"usa_spending_actual":0.0}]
A43: 14.252 | B43: Section 4 Capacity Building for Community Development and Affordable Housing | C43: Section 4 Capacity Building | D43: Department of Housing and Urban Development | E43: Assistant Secretary for Community Planning and Development | F43: The Section 4 program builds the capacity of Community Development Corporations (CDCs) and Community Housing Development Organizations (CHDOs) to serve their communities and low- and moderate-income families with community development and affordable housing activities. | G43: Project Grants | H43: Private nonprofit institution/organization | I43: Other private institutions/organizations | J43: 0 | K43: 83000000 | L43: 41000000 | M43: [{"x":"2023","sam_estimate":0.0,"sam_actual":41000000.0,"usa_spending_actual":41000000.0},{"x":"2024","sam_estimate":0.0,"sam_actual":83000000.0,"usa_spending_actual":83000000.0},{"x":"2025","sam_estimate":0.0,"sam_actual":0.0,"usa_spending_actual":0.0}]
A44: 14.256 | B44: Neighborhood Stabilization Program (Recovery Act Funded) | D44: Department of Housing and Urban Development | E44: Office of Community Planning and Development | F44: Neighborhood stabilization through acquisition and rehabilitation, land banking, disposition, or demolition of abandoned and foreclosed residential property. Also, to develop viable urban communities, by providing decent housing and a suitable living environment, and by expanding economic opportunities, principally for persons of low and moderate income. | G44: Project Grants | H44: Low Income | I44: Government - General,Local (includes State-designated lndian Tribes, excludes institutions of higher education and hospitals,Private nonprofit institution/organization (includes institutions of higher education and hospitals),Public nonprofit institution/organization (includes institutions of higher education and hospitals),State (includes District of Columbia, public institutions of higher education and hospitals) | J44: 0 | K44: 0 | L44: 0 | M44: [{"x":"2023","sam_estimate":0.0,"sam_actual":0.0,"usa_spending_actual":0.0},{"x":"2024","sam_estimate":0.0,"sam_actual":0.0,"usa_spending_actual":0.0},{"x":"2025","sam_estimate":0.0,"sam_actual":0.0,"usa_spending_actual":0.0}]
A45: 14.259 | B45: Community Compass Technical Assistance and Capacity Building | C45: Community Compass TA | D45: Department of Housing and Urban Development | E45: Assistant Secretary for Policy Development and Research | F45: Community Compass brings together technical assistance funding appropriations from across HUD program offices, including the offices of Community Planning and Development, Fair Housing and Equal Opportunity, Housing, Public and Indian Housing, and Policy Development and Research. This cross-funding approach recognizes that HUD’s grantees, subgrantees, and other customers often interact with a variety of HUD programs as they deliver housing or community development services. Community Compass allows for holistic technical assistance to address the program and policy implementation deficiencies and skill gaps of grantees and subgrantees across multiple HUD programs, often within the same engagement. | G45: Project Grants | H45: Federally Recognized Indian Tribal Governments,Local,Public nonprofit institution/organization,Sponsored organization,State,U.S. Territories | I45: Federally Recognized lndian Tribal Governments,Native American Organizations (includes lndian groups, cooperatives, corporations, partnerships, associations),Other private institutions/organizations,Private nonprofit institution/organization (includes institutions of higher education and hospitals),Profit organization,Public nonprofit institution/organization (includes institutions of higher education and hospitals),Small business (less than 500 employees),State,State (includes District of Columbia, public institutions of higher education and hospitals) | J45: 0 | K45: -1060000 | L45: 1.5277355e+08 | M45: [{"x":"2023","sam_estimate":0.0,"sam_actual":184833190.0,"usa_spending_actual":152773550.14},{"x":"2024","sam_estimate":0.0,"sam_actual":69303801.0,"usa_spending_actual":-1060000.0},{"x":"2025","sam_estimate":0.0,"sam_actual":69936955.0,"usa_spending_actual":0.0}]
A46: 14.261 | B46: National Homeless Data Analysis Project (NHDAP) | C46: National Homeless Data Analysis Project (NHDAP) | D46: Department of Housing and Urban Development | E46: Assistant Secretary for Community Planning and Development | F46: National Homeless Data Analysis Project (NHDAP) provides critical resources to HUD and the homelessness response systems to improve homelessness response data collection, analysis, and reporting; integrate data collection efforts in Homeless Management Information Systems (HMIS) with other federal funding streams; enhance the ability for HUD and communities to report and analyze data about persons experiencing homelessness; produce standards and specifications for data entry and reporting for all HMIS-generated reports, analyze point-in-time and longitudinal analysis system data to produce the Annual Homeless Assessment Report (AHAR); and provide technical assistance on HMIS implementation. | G46: Project Grants | H46: Local,Private nonprofit institution/organization,Public nonprofit institution/organization,State | I46: Non-Government - General,Other public institution/organization,State | J46: 0 | K46: -588329.39 | L46: -175157.19 | M46: [{"x":"2023","sam_estimate":0.0,"sam_actual":4550000.0,"usa_spending_actual":-175157.19},{"x":"2024","sam_estimate":0.0,"sam_actual":9350000.0,"usa_spending_actual":-588329.39},{"x":"2025","sam_estimate":0.0,"sam_actual":0.0,"usa_spending_actual":0.0}]
A47: 14.265 | B47: Rural Capacity Building for Community Development and Affordable Housing Grants | C47: Rural Capacity Building Program | D47: Department of Housing and Urban Development | E47: Assistant Secretary for Community Planning and Development | F47: The Rural Capacity Building program enhances the capacity and ability of rural housing development organizations, Community Development Corporations (CDCs), Community Housing Development Organizations (CHDOs), local governments, and Indian tribes (eligible beneficiaries) to carry out affordable housing and community development activities in rural areas for the benefit of low- and moderate-income families and persons. The Rural Capacity Building program achieves this by funding National Organizations with expertise in rural housing and rural community development who work directly to build the capacity of eligible beneficiaries. | G47: Project Grants | H47: Federally Recognized Indian Tribal Governments,Local,Private nonprofit institution/organization | I47: Other private institutions/organizations | J47: 0 | K47: 0 | L47: 9231410.4 | M47: [{"x":"2023","sam_estimate":0.0,"sam_actual":10000000.0,"usa_spending_actual":9231410.43},{"x":"2024","sam_estimate":0.0,"sam_actual":6000000.0,"usa_spending_actual":0.0},{"x":"2025","sam_estimate":0.0,"sam_actual":0.0,"usa_spending_actual":0.0}]
A48: 14.267 | B48: Continuum of Care Program | C48: See Notice of Funding Opportunity [NOFO] for additional information. | D48: Department of Housing and Urban Development | E48: Assistant Secretary for Community Planning and Development | F48: The program is designed to promote community-wide commitment to the goal of ending homelessness; provide funding for efforts by nonprofit providers, States, and local governments to quickly house homeless individuals and families while minimizing the trauma and dislocation caused to homeless individuals, families, and communities by homelessness; promote access to and effective utilization of mainstream programs by homeless individuals and families; and optimize self-sufficiency among individuals and families experiencing homelessness. Continuum of Care Program funds may be used to pay for the eligible costs used to establish and operate projects under five program components: (i) permanent housing, which includes permanent supportive housing for persons with disabilities, and rapid rehousing; (ii) transitional housing; (iii) supportive services only; (iv) Homeless Management Information Systems (HMIS), and (v) in some cases, homelessness prevention. | G48: Project Grants | H48: Individual/Family | I48: Government - General,Local (includes State-designated lndian Tribes, excludes institutions of higher education and hospitals,Other private institutions/organizations,Quasi-public nonprofit institution/organization,Specialized group (e.g. health professionals, students, veterans),State | J48: 0 | K48: 2965446336 | L48: 2.5883551e+09 | M48: [{"x":"2023","sam_estimate":0.0,"sam_actual":3261008611.0,"usa_spending_actual":2588355061.93},{"x":"2024","sam_estimate":0.0,"sam_actual":3192650000.0,"usa_spending_actual":2965446336.0},{"x":"2025","sam_estimate":0.0,"sam_actual":0.0,"usa_spending_actual":69568361.82}]
A49: 14.269 | B49: Hurricane Sandy Community Development Block Grant Disaster Recovery Grants (CDBG-DR) | C49: Community Development Block Grant Disaster Recovery program for Hurricane Sandy and other qualifying disasters occurring in 2011, 2012 and 2013 | D49: Department of Housing and Urban Development | E49: Assistant Secretary for Community Planning and Development | F49: The overall CDBG program objective is to develop viable urban communities, by providing decent housing and a suitable living environment, and by expanding economic opportunities, principally for persons of low and moderate income. CDBG DR program funds appropriated by P.L. 113-2 are for necessary expenses related to disaster relief, long-term recovery, restoration of infrastructure and housing, and economic revitalization in the most impacted and distressed areas resulting from a major disaster declaration due to Hurricane Sandy and other eligible events in calendar years 2011, 2012, and 2013. | G49: Formula Grants | H49: Homeowner,Individual/Family,Low Income,Moderate Income,Private nonprofit institution/organization,Public nonprofit institution/organization,Small business | I49: Local (includes State-designated lndian Tribes, excludes institutions of higher education and hospitals,State,U.S. Territories and possessions | J49: 0 | K49: -140842.94 | L49: -1 | M49: [{"x":"2023","sam_estimate":0.0,"sam_actual":0.0,"usa_spending_actual":-1.0},{"x":"2024","sam_estimate":0.0,"sam_actual":0.0,"usa_spending_actual":-140842.94},{"x":"2025","sam_estimate":0.0,"sam_actual":0.0,"usa_spending_actual":0.0}]
A50: 14.272 | B50: National Disaster Resilience Competition | C50: Community Development Block Grant P. L. 113-2 | D50: Department of Housing and Urban Development | E50: Assistant Secretary for Community Planning and Development | F50: The overall CDBG program objective is to develop viable urban communities, by providing decent housing and a suitable living environment, and by expanding economic opportunities, principally for persons of low and moderate income. The National Resilient Disaster Competition program funds appropriated by P.L. 113-2 are available for resilient recovery projects and necessary expenses related to disaster relief, long-term recovery, restoration of infrastructure and housing, and economic revitalization in the most impacted and distressed areas resulting from a major disaster declared pursuant to the due to Hurricane Sandy and other eligible events in calendar years 2011, 2012, and 2013. | G50: Project Grants | H50: Anyone/general public,Homeowner,Interstate,Local,Low Income,Moderate Income,Private nonprofit institution/organization,Profit organization,Public nonprofit institution/organization,Senior Citizen (60+),Small business,State | I50: Local (includes State-designated lndian Tribes, excludes institutions of higher education and hospitals,State,U.S. Territories and possessions | J50: 0 | K50: 0 | L50: -606138.41 | M50: [{"x":"2023","sam_estimate":0.0,"sam_actual":0.0,"usa_spending_actual":-606138.41},{"x":"2024","sam_estimate":0.0,"sam_actual":0.0,"usa_spending_actual":0.0},{"x":"2025","sam_estimate":0.0,"sam_actual":0.0,"usa_spending_actual":0.0}]
A51: 14.275 | B51: Housing Trust Fund | C51: Housing Trust Fund | D51: Department of Housing and Urban Development | E51: Assistant Secretary for Community Planning and Development | F51: To expand and preserve the supply of affordable housing, particularly rental housing, for extremely low-income and very low income households. | G51: Formula Grants | H51: State | I51: State | J51: 0 | K51: 2.0558172e+08 | L51: 6.8655661e+08 | M51: [{"x":"2023","sam_estimate":0.0,"sam_actual":688096848.0,"usa_spending_actual":686556608.11},{"x":"2024","sam_estimate":0.0,"sam_actual":216961850.0,"usa_spending_actual":205581716.74},{"x":"2025","sam_estimate":0.0,"sam_actual":278000000.0,"usa_spending_actual":40280086.6}]
